<robot name="bumblebee">
    <link name="world" />
    <joint name="base_joint" type="fixed">
        <origin xyz="0 0 0" rpy="0 0 0 " />
        <parent link="world" />
        <child link="base" />
    </joint>
    <link name="base">
        <visual>
            <geometry>
                <mesh filename="package://bb_description/meshes/visual/Base.dae" />
            </geometry>
        </visual>
        <collision>
            <geometry>
                <mesh filename="package://bb_description/meshes/collision/Base.stl" />
            </geometry>
        </collision>

        <inertial>
            <mass value="0.403" />
            <inertia ixx="0.0027" iyy="0.0027" izz="0.0001" ixy="0.0" ixz="0.0" iyz="0.0" />
        </inertial>

    </link>
    <link name="link1">
        <visual>
            <geometry>
                <mesh filename="package://bb_description/meshes/visual/Link1.dae" />
            </geometry>
        </visual>
        <collision>
            <geometry>
                <mesh filename="package://bb_description/meshes/collision/Link1.stl" />
            </geometry>
        </collision>

        <inertial>
            <mass value="0.511" />
            <inertia ixx="0.0331" iyy="0.0320" izz="0.0016" ixy="0.0" ixz="0.0" iyz="-0.0048" />
        </inertial>

    </link>
    <link name="link2">
        <visual>
            <geometry>
                <mesh filename="package://bb_description/meshes/visual/Link2.dae" />
            </geometry>
        </visual>
        <collision>
            <geometry>
                <mesh filename="package://bb_description/meshes/collision/Link2.stl" />
            </geometry>
        </collision>

        <inertial>
            <mass value="1.123" />
            <inertia ixx="0.1814" iyy="0.1730" izz="0.0096" ixy="0.0" ixz="0.0" iyz="0.0338" />
        </inertial>

    </link>
    <link name="link3">
        <visual>
            <geometry>
                <mesh filename="package://bb_description/meshes/visual/Link3.dae" />
            </geometry>
        </visual>
        <collision>
            <geometry>
                <mesh filename="package://bb_description/meshes/collision/Link3.stl" />
            </geometry>
        </collision>

        <inertial>
            <mass value="0.432" />
            <inertia ixx="0.1210" iyy="0.1200" izz="0.0014" ixy="0.0" ixz="0.0" iyz="-0.0077" />
        </inertial>

    </link>
    <link name="link4">
        <visual>
            <geometry>
                <mesh filename="package://bb_description/meshes/visual/Link4.dae" />
            </geometry>
        </visual>
        <collision>
            <geometry>
                <mesh filename="package://bb_description/meshes/collision/Link4.stl" />
            </geometry>
        </collision>

        <inertial>
            <mass value="0.214" />
            <inertia ixx="0.1030" iyy="0.1029" izz="0.0002" ixy="0.0" ixz="0.0" iyz="-0.0010" />
        </inertial>

    </link>
    <link name="link5">
        <visual>
            <geometry>
                <mesh filename="package://bb_description/meshes/visual/Link5.dae" />
            </geometry>
        </visual>
        <collision>
            <geometry>
                <mesh filename="package://bb_description/meshes/collision/Link5.stl" />
            </geometry>
        </collision>

        <inertial>
            <mass value="0.214" />
            <inertia ixx="0.1318" iyy="0.1318" izz="0.0002" ixy="0.0" ixz="0.0" iyz="0.0024" />
        </inertial>

    </link>
    <link name="link6">

        <inertial>
            <mass value="0.027" />
            <inertia ixx="0.0194" iyy="0.0194" izz="0.0" ixy="0.0" ixz="0.0" iyz="0.0" />
        </inertial>

    </link>
    <link name="gripper_tool">
        <visual>
            <geometry>
                <mesh filename="package://bb_description/meshes/visual/GripperTool.dae" />
            </geometry>
        </visual>
        <collision>
            <geometry>
                <mesh filename="package://bb_description/meshes/collision/GripperTool.stl" />
            </geometry>
        </collision>

        <inertial>
            <mass value="0.135" />
            <inertia ixx="0.1065" iyy="0.1065" izz="0.0" ixy="0.0" ixz="0.0" iyz="0.0001" />
        </inertial>

    </link>
    <link name="gripper_left">
        <visual>
            <geometry>
                <mesh filename="package://bb_description/meshes/visual/GripperLeft.dae" />
            </geometry>
        </visual>
        <collision>
            <geometry>
                <mesh filename="package://bb_description/meshes/collision/GripperLeft.stl" />
            </geometry>
        </collision>

        <inertial>
            <mass value="0.026" />
            <inertia ixx="0.0233" iyy="0.0233" izz="0.0" ixy="0.0" ixz="0.0" iyz="0.0001" />
        </inertial>

    </link>
    <link name="gripper_right">
        <visual>
            <geometry>
                <mesh filename="package://bb_description/meshes/visual/GripperRight.dae" />
            </geometry>
        </visual>
        <collision>
            <geometry>
                <mesh filename="package://bb_description/meshes/collision/GripperRight.stl" />
            </geometry>
        </collision>

        <inertial>
            <mass value="0.026" />
            <inertia ixx="0.0231" iyy="0.0231" izz="0.0" ixy="0.0" ixz="0.0" iyz="0.0" />
        </inertial>

    </link>
    <link name="EE" />
    <link name="Gear"/>

    <joint name="joint1" type="revolute">
        <origin xyz="0 0 0.110555" rpy="0 0 0 " />
        <limit lower="-2.6" upper="2.6" effort="3.0" velocity="6" />
        <parent link="base" />
        <child link="link1" />
        <axis xyz="0 0 1" />
        <safety_controller k_position="100.0" k_velocity="40.0" soft_lower_limit="-2.58" soft_upper_limit="2.58" />
    </joint>
    <joint name="joint2" type="revolute">
        <origin xyz="0 0 0.175" rpy="-1.57 0 0 " />
        <limit lower="-2.6" upper="2.6" effort="3.0" velocity="6" />
        <parent link="link1" />
        <child link="link2" />
        <axis xyz="0 0 1" />
        <safety_controller k_position="100.0" k_velocity="40.0" soft_lower_limit="-2.58" soft_upper_limit="2.58" />
    </joint>
    <joint name="joint3" type="revolute">
        <origin xyz="0 -0.175 0" rpy="0 0 0 " />
        <limit lower="-2.6" upper="2.6" effort="3.0" velocity="6" />
        <parent link="link2" />
        <child link="link3" />
        <axis xyz="0 0 1" />
        <safety_controller k_position="100.0" k_velocity="40.0" soft_lower_limit="-2.58" soft_upper_limit="2.58" />
    </joint>
    <joint name="joint4" type="revolute">
        <origin xyz="0 -0.15111 0" rpy="1.57 0 0 " />
        <limit lower="-2.6" upper="2.6" effort="2.0" velocity="12" />
        <parent link="link3" />
        <child link="link4" />
        <axis xyz="0 0 1" />
        <safety_controller k_position="100.0" k_velocity="40.0" soft_lower_limit="-2.58" soft_upper_limit="2.58" />
    </joint>
    <joint name="joint5" type="revolute">
        <origin xyz="0 0 0.110555" rpy="-1.57 0 0 " />
        <limit lower="-2.6" upper="2.6" effort="2.0" velocity="12" />
        <parent link="link4" />
        <child link="link5" />
        <axis xyz="0 0 1" />
        <safety_controller k_position="100.0" k_velocity="40.0" soft_lower_limit="-2.58" soft_upper_limit="2.58" />
    </joint>
    <joint name="joint6" type="revolute">
        <origin xyz="0 -0.110555 0" rpy="1.57 0 0 " />
        <limit lower="-2.6" upper="2.6" effort="2.0" velocity="12" />
        <parent link="link5" />
        <child link="link6" />
        <axis xyz="0 0 1" />
        <safety_controller k_position="100.0" k_velocity="40.0" soft_lower_limit="-2.58" soft_upper_limit="2.58" />
    </joint>
    <joint name="joint_gripper" type="fixed">
        <origin xyz="0 0 0" rpy="0 0 0 " />
        <parent link="link6" />
        <child link="gripper_tool" />
        <axis xyz="0 0 0" />
    </joint>
    <joint name="joint7" type="revolute">
        <origin xyz="0 0 0.085524" rpy="0 1.57 0 " />
        <limit lower="-2.6" upper="2.6" effort="2.0" velocity="12" />
        <parent link="gripper_tool" />
        <child link="Gear"/>
        <axis xyz="0 0 1" />
        <safety_controller k_position="100.0" k_velocity="40.0" soft_lower_limit="-2.58" soft_upper_limit="2.58" />
    </joint>
    <joint name="joint_gripper_left" type="revolute">
        <origin xyz="0 -0.014 0.085524" rpy="0 1.57 0 " />
        <limit lower="-2.6" upper="2.6" effort="2.0" velocity="12" />
        <parent link="gripper_tool" />
        <child link="gripper_left" />
        <mimic joint="joint7" multiplier="-0.75"/>
        <axis xyz="0 0 1" />
        <safety_controller k_position="100.0" k_velocity="40.0" soft_lower_limit="-2.58" soft_upper_limit="2.58" />
    </joint>
    <joint name="joint_gripper_right" type="revolute">
        <origin xyz="0 0.014 0.085524" rpy="0 1.57 0 " />
        <limit lower="-2.6" upper="2.6" effort="2.0" velocity="12" />
        <parent link="gripper_tool" />
        <child link="gripper_right" />
        <mimic joint="joint7" multiplier="0.75"/>
        <axis xyz="0 0 1" />
        <safety_controller k_position="100.0" k_velocity="40.0" soft_lower_limit="-2.58" soft_upper_limit="2.58" />
    </joint>
    <joint name="joint_EE" type="fixed">
        <origin xyz="0 0 0.175524" rpy="0 0 0 " />
        <parent link="link6" />
        <child link="EE" />
    </joint>

    
    <transmission name="trans_joint1">
        <type>transmission_interface/SimpleTransmission</type>
        <joint name="joint1">
            <hardwareInterface>hardware_interface/PositionJointInterface</hardwareInterface>
        </joint>
        <actuator name="joint1_motor">
            <hardwareInterface>hardware_interface/PositionJointInterface</hardwareInterface>
            <mechanicalReduction>1</mechanicalReduction>
        </actuator>
    </transmission>
    <transmission name="trans_joint2">
        <type>transmission_interface/SimpleTransmission</type>
        <joint name="joint2">
            <hardwareInterface>hardware_interface/PositionJointInterface</hardwareInterface>
        </joint>
        <actuator name="joint2_motor">
            <hardwareInterface>hardware_interface/PositionJointInterface</hardwareInterface>
            <mechanicalReduction>1</mechanicalReduction>
        </actuator>
    </transmission>
    <transmission name="trans_joint3">
        <type>transmission_interface/SimpleTransmission</type>
        <joint name="joint3">
            <hardwareInterface>hardware_interface/PositionJointInterface</hardwareInterface>
        </joint>
        <actuator name="joint3_motor">
            <hardwareInterface>hardware_interface/PositionJointInterface</hardwareInterface>
            <mechanicalReduction>1</mechanicalReduction>
        </actuator>
    </transmission>
    <transmission name="trans_joint4">
        <type>transmission_interface/SimpleTransmission</type>
        <joint name="joint4">
            <hardwareInterface>hardware_interface/PositionJointInterface</hardwareInterface>
        </joint>
        <actuator name="joint4_motor">
            <hardwareInterface>hardware_interface/PositionJointInterface</hardwareInterface>
            <mechanicalReduction>1</mechanicalReduction>
        </actuator>
    </transmission>
    <transmission name="trans_joint5">
        <type>transmission_interface/SimpleTransmission</type>
        <joint name="joint5">
            <hardwareInterface>hardware_interface/PositionJointInterface</hardwareInterface>
        </joint>
        <actuator name="joint5_motor">
            <hardwareInterface>hardware_interface/PositionJointInterface</hardwareInterface>
            <mechanicalReduction>1</mechanicalReduction>
        </actuator>
    </transmission>
    <transmission name="trans_joint6">
        <type>transmission_interface/SimpleTransmission</type>
        <joint name="joint6">
            <hardwareInterface>hardware_interface/PositionJointInterface</hardwareInterface>
        </joint>
        <actuator name="joint6_motor">
            <hardwareInterface>hardware_interface/PositionJointInterface</hardwareInterface>
            <mechanicalReduction>1</mechanicalReduction>
        </actuator>
    </transmission>
    <transmission name="trans_joint7">
        <type>transmission_interface/SimpleTransmission</type>
        <joint name="joint7">
            <hardwareInterface>hardware_interface/PositionJointInterface</hardwareInterface>
        </joint>
        <actuator name="joint7_motor">
            <hardwareInterface>hardware_interface/PositionJointInterface</hardwareInterface>
            <mechanicalReduction>1</mechanicalReduction>
        </actuator>
    </transmission>
    <transmission name="trans_joint_gripper_left">
        <type>transmission_interface/SimpleTransmission</type>
        <joint name="joint_gripper_left">
            <hardwareInterface>hardware_interface/PositionJointInterface</hardwareInterface>
        </joint>
        <actuator name="joint_gripper_left_motor">
            <hardwareInterface>hardware_interface/PositionJointInterface</hardwareInterface>
            <mechanicalReduction>1</mechanicalReduction>
        </actuator>
    </transmission>
    <transmission name="trans_joint_gripper_right">
        <type>transmission_interface/SimpleTransmission</type>
        <joint name="joint_gripper_right">
            <hardwareInterface>hardware_interface/PositionJointInterface</hardwareInterface>
        </joint>
        <actuator name="joint_gripper_right_motor">
            <hardwareInterface>hardware_interface/PositionJointInterface</hardwareInterface>
            <mechanicalReduction>1</mechanicalReduction>
        </actuator>
    </transmission>
    <gazebo>
        <plugin name="gazebo_ros_control" filename="libgazebo_ros_control.so">
            <robotNamespace>/</robotNamespace>
        </plugin>
    </gazebo>
</robot>